Invalid HTTP_HOST header: '45.76.216.210'. You may need to add u'45.76.216.210' to ALLOWED_HOSTS.
[14/Oct/2017 17:35:10] "GET / HTTP/1.1" 400 60877
python: can't open file 'runserver': [Errno 2] No such file or directory
python: can't open file 'runserver': [Errno 2] No such file or directory
python: can't open file 'runserver': [Errno 2] No such file or directory
python: can't open file 'mamanage.py': [Errno 2] No such file or directory
python: can't open file 'mamanage.py': [Errno 2] No such file or directory
[14/Oct/2017 17:46:44] "GET / HTTP/1.1" 200 1716
[14/Oct/2017 17:50:24] "GET / HTTP/1.1" 200 1716
Not Found: /tag/reon-otowa/
[14/Oct/2017 17:53:09] "GET /tag/reon-otowa/ HTTP/1.1" 404 1982
Not Found: /upload/2015/249.jpg
[14/Oct/2017 18:04:34] "GET /upload/2015/249.jpg HTTP/1.1" 404 1994
Performing system checks...

System check identified no issues (0 silenced).
October 14, 2017 - 17:46:43
Django version 1.11.6, using settings 'djaongo_bookmarks.settings'
Starting development server at http://45.76.216.210:80/
Quit the server with CONTROL-C.
Unhandled exception in thread started by <function wrapper at 0x320ac80>
Performing system checks...

Traceback (most recent call last):
  File "/usr/lib64/python2.7/site-packages/django/utils/autoreload.py", line 228, in wrapper
    fn(*args, **kwargs)
  File "/usr/lib64/python2.7/site-packages/django/core/management/commands/runserver.py", line 125, in inner_run
    self.check(display_num_errors=True)
  File "/usr/lib64/python2.7/site-packages/django/core/management/base.py", line 359, in check
    include_deployment_checks=include_deployment_checks,
  File "/usr/lib64/python2.7/site-packages/django/core/management/base.py", line 346, in _run_checks
    return checks.run_checks(**kwargs)
  File "/usr/lib64/python2.7/site-packages/django/core/checks/registry.py", line 81, in run_checks
    new_errors = check(app_configs=app_configs)
  File "/usr/lib64/python2.7/site-packages/django/core/checks/urls.py", line 16, in check_url_config
    return check_resolver(resolver)
  File "/usr/lib64/python2.7/site-packages/django/core/checks/urls.py", line 26, in check_resolver
    return check_method()
  File "/usr/lib64/python2.7/site-packages/django/urls/resolvers.py", line 254, in check
    for pattern in self.url_patterns:
  File "/usr/lib64/python2.7/site-packages/django/utils/functional.py", line 35, in __get__
    res = instance.__dict__[self.name] = self.func(instance)
  File "/usr/lib64/python2.7/site-packages/django/urls/resolvers.py", line 405, in url_patterns
    patterns = getattr(self.urlconf_module, "urlpatterns", self.urlconf_module)
  File "/usr/lib64/python2.7/site-packages/django/utils/functional.py", line 35, in __get__
    res = instance.__dict__[self.name] = self.func(instance)
  File "/usr/lib64/python2.7/site-packages/django/urls/resolvers.py", line 398, in urlconf_module
    return import_module(self.urlconf_name)
  File "/usr/lib64/python2.7/importlib/__init__.py", line 37, in import_module
    __import__(name)
  File "/home/ftpuser/python/django_bookmarks/djaongo_bookmarks/urls.py", line 20, in <module>
    from django.conf.urls.defaults import *
ImportError: No module named defaults
[14/Oct/2017 18:26:42] "GET / HTTP/1.1" 200 291
[14/Oct/2017 18:27:11] "GET /video/phim-sex-hd-dit-me-ke-full-khong-che/41/ HTTP/1.1" 404 2035
[14/Oct/2017 18:28:13] "GET / HTTP/1.1" 200 291
